<?xml version="1.0"?>

<sdf version="1.6">
<!-- Basic model of the 16' WAM-V USV -->
<model name="wamv2">
  <static>false</static>
  <link name="base_link">
    <enable_wind>true</enable_wind>
    <inertial>
      <pose>0 0 -0.6 0 0 0</pose>
      <mass>50</mass>
      <inertia>
        <ixx>120.4</ixx>
        <ixy>0</ixy>
        <ixz>0</ixz>
        <iyy>240.25</iyy>
        <iyz>0</iyz>
        <izz>360.25</izz>
      </inertia>
    </inertial>

    <visual name="visual">
      <pose>-0.45 -10.35 -0.225 0 0 1.570796327</pose>
      <geometry>
        <mesh><uri>meshes/warship.dae</uri><scale>1.5 1.5 1.5</scale></mesh>
      </geometry>
    </visual>

    <collision name="collision">
      <pose>-0.6 0 0.5 0 0 0</pose>
      <geometry>
        <box>
          <size>6 1.2 1.2</size>
        </box>
      </geometry>
    </collision>
  </link>

  <!-- left engine and thruster -->
  <link name="left_housing_link">
    <inertial>
      <pose>0 0.495 -0.225 0 0 0</pose>
      <mass>0.5</mass>
      <inertia>
        <ixx>0.00121745</ixx>
        <ixy>0</ixy>
        <ixz>0</ixz>
        <iyy>0.001445</iyy>
        <iyz>0</iyz>
        <izz>0.00041245</izz>
      </inertia>
    </inertial>
    <visual name="left_housing_visual">
      <pose>0 0.495 -0.225 0 0 0</pose>
      <geometry>
        <mesh>
          <uri>meshes/housing.dae</uri>
        <scale>1.5 1.5 1.5</scale></mesh>
      </geometry>
      <material>
        <diffuse>1 1 1</diffuse>
        <specular>1 1 1</specular>
        <pbr>
          <metal>
            <albedo_map>materials/textures/Thruster_Albedo.png</albedo_map>
            <roughness_map>materials/textures/Thruster_Roughness.png</roughness_map>
          </metal>
        </pbr>
      </material>
    </visual>
    <visual name="left_mount_visual">
      <pose>0 0.495 -0.225 0 0 0</pose>
      <geometry>
        <mesh>
          <uri>meshes/mount.dae</uri>
        <scale>1.5 1.5 1.5</scale></mesh>
      </geometry>
      <material>
        <diffuse>1 1 1</diffuse>
        <specular>1 1 1</specular>
        <pbr>
          <metal>
            <albedo_map>materials/textures/Thruster_Albedo.png</albedo_map>
            <roughness_map>materials/textures/Thruster_Roughness.png</roughness_map>
          </metal>
        </pbr>
      </material>
    </visual>
    <collision name="Box011d">
      <pose>0 0.495 -0.0735735 0 0 0</pose>
      <geometry>
        <box>
          <size>0.12156795 0.06457785 0.1063875</size>
        </box>
      </geometry>
    </collision>
    <collision name="Cylinder264d">
      <pose>0 0.495 -0.1307901 0 0 0</pose>
      <geometry>
        <cylinder>
          <length>0.1884195</length>
          <radius>0.0220545</radius>
        </cylinder>
      </geometry>
    </collision>
    <collision name="Cylinder263d">
      <pose>0.0 0.495 -0.225 1.5708 0 -1.5708</pose>
      <geometry>
        <cylinder>
          <length>0.21564</length>
          <radius>0.0365538</radius>
        </cylinder>
      </geometry>
    </collision>
  </link>

  <link name="left_prop_link">
    <inertial>
      <pose>0 0.495 -0.225 0 0 0</pose>
      <mass>0.25</mass>
      <inertia>
        <ixx>0.00063375</ixx>
        <ixy>0</ixy>
        <ixz>0</ixz>
        <iyy>0.00063375</iyy>
        <iyz>0</iyz>
        <izz>0.0009075</izz>
      </inertia>
    </inertial>
    <visual name="left_prop_visual">
      <pose>0 0.495 -0.225 0 0 0</pose>
      <geometry>
        <mesh>
          <uri>meshes/prop.dae</uri>
        <scale>1.5 1.5 1.5</scale></mesh>
      </geometry>
      <material>
        <diffuse>1 1 1</diffuse>
        <specular>1 1 1</specular>
        <pbr>
          <metal>
            <albedo_map>materials/textures/Thruster_Albedo.png</albedo_map>
            <roughness_map>materials/textures/Thruster_Roughness.png</roughness_map>
          </metal>
        </pbr>
      </material>
    </visual>
    <collision name="Cylinder262d">
      <pose>0.0 0.495 -0.225 1.5708 0 -1.5708</pose>
      <geometry>
        <cylinder>
          <length>0.0912258</length>
          <radius>0.0830766</radius>
        </cylinder>
      </geometry>
    </collision>
  </link>

  <joint name="left_chasis_engine_joint" type="revolute">
    <axis>
      <xyz>0 0 1</xyz>
      <limit>
        <lower>0</lower>
        <upper>0</upper>
        <effort>10</effort>
        <velocity>10</velocity>
      </limit>
    </axis>
    <parent>base_link</parent>
    <child>left_housing_link</child>
  </joint>
  
  <joint name="left_engine_propeller_joint" type="revolute">
    <pose>0.0 0.495 -0.225 1.5708 0 0</pose>
    <axis>
      <xyz>1 0 0</xyz>
      <limit>
        <effort>100</effort>
        <velocity>100</velocity>
      </limit>
      <dynamics>
        <friction>0.05</friction>
        <damping>0.05</damping>
      </dynamics>
    </axis>
    <parent>left_housing_link</parent>
    <child>left_prop_link</child>
  </joint>

  <!-- right engine and thruster -->
  <link name="right_housing_link">
    <inertial>
      <pose>0.0 -0.495 -0.225 0 0 0</pose>
      <mass>0.5</mass>
      <inertia>
        <ixx>0.00121745</ixx>
        <ixy>0</ixy>
        <ixz>0</ixz>
        <iyy>0.001445</iyy>
        <iyz>0</iyz>
        <izz>0.00041245</izz>
      </inertia>
    </inertial>
    <visual name="right_housing_visual">
      <pose>0.0 -0.495 -0.225 0 0 0</pose>
      <geometry>
        <mesh>
          <uri>meshes/housing.dae</uri>
        <scale>1.5 1.5 1.5</scale></mesh>
      </geometry>
      <material>
        <diffuse>1 1 1</diffuse>
        <specular>1 1 1</specular>
        <pbr>
          <metal>
            <albedo_map>materials/textures/Thruster_Albedo.png</albedo_map>
            <roughness_map>materials/textures/Thruster_Roughness.png</roughness_map>
          </metal>
        </pbr>
      </material>
    </visual>
    <visual name="right_mount_visual">
      <pose>0.0 -0.495 -0.225 0 0 0</pose>
      <geometry>
        <mesh>
          <uri>meshes/mount.dae</uri>
        <scale>1.5 1.5 1.5</scale></mesh>
      </geometry>
      <material>
        <diffuse>1 1 1</diffuse>
        <specular>1 1 1</specular>
        <pbr>
          <metal>
            <albedo_map>materials/textures/Thruster_Albedo.png</albedo_map>
            <roughness_map>materials/textures/Thruster_Roughness.png</roughness_map>
          </metal>
        </pbr>
      </material>
    </visual>
    <collision name="Box011i">
      <pose>0.0 -0.495 -0.0735735 0 0 0</pose>
      <geometry>
        <box>
          <size>0.12156795 0.06457785 0.1063875</size>
        </box>
      </geometry>
    </collision>
    <collision name="Cylinder264i">
      <pose>0.0 -0.495 -0.1307901 0 0 0</pose>
      <geometry>
        <cylinder>
          <length>0.1884195</length>
          <radius>0.0220545</radius>
        </cylinder>
      </geometry>
    </collision>
    <collision name="Cylinder263i">
      <pose>0.0 -0.495 -0.225 1.5708 0 -1.5708</pose>
      <geometry>
        <cylinder>
          <length>0.21564</length>
          <radius>0.0365538</radius>
        </cylinder>
      </geometry>
    </collision>
  </link>
  
  <link name="right_prop_link">
    <inertial>
      <pose>0.0 -0.495 -0.225 0 0 0</pose>
      <mass>0.25</mass>
      <inertia>
        <ixx>0.00063375</ixx>
        <ixy>0</ixy>
        <ixz>0</ixz>
        <iyy>0.00063375</iyy>
        <iyz>0</iyz>
        <izz>0.0009075</izz>
      </inertia>
    </inertial>
    <visual name="right_prop_visual">
      <pose>0.0 -0.495 -0.225 0 0 0</pose>
      <geometry>
        <mesh>
          <uri>meshes/prop.dae</uri>
        <scale>1.5 1.5 1.5</scale></mesh>
      </geometry>
      <material>
        <diffuse>1 1 1</diffuse>
        <specular>1 1 1</specular>
        <pbr>
          <metal>
            <albedo_map>materials/textures/Thruster_Albedo.png</albedo_map>
            <roughness_map>materials/textures/Thruster_Roughness.png</roughness_map>
          </metal>
        </pbr>
      </material>
    </visual>
    <collision name="Cylinder262i">
      <pose>0.0 -0.495 -0.225 1.5708 0 -1.5708</pose>
      <geometry>
        <cylinder>
          <length>0.0912258</length>
          <radius>0.0830766</radius>
        </cylinder>
      </geometry>
    </collision>
  </link>

  <joint name="right_chasis_engine_joint" type="revolute">
    <axis>
      <xyz>0 0 1</xyz>
      <limit>
        <lower>0</lower>
        <upper>0</upper>
        <effort>10</effort>
        <velocity>10</velocity>
      </limit>
    </axis>
    <parent>base_link</parent>
    <child>right_housing_link</child>
  </joint>
  
  <joint name="right_engine_propeller_joint" type="revolute">
    <pose>0.0 -0.495 -0.225 1.5708 0 0</pose>
    <axis>
      <xyz>1 0 0</xyz>
      <limit>
        <effort>100</effort>
        <velocity>100</velocity>
      </limit>
      <dynamics>
        <friction>0.05</friction>
        <damping>0.05</damping>
      </dynamics>
    </axis>
    <parent>right_housing_link</parent>
    <child>right_prop_link</child>
  </joint>

  <!-- Uncomment to enable the left thruster -->
  <plugin filename="gz-sim-thruster-system" name="gz::sim::systems::Thruster">
    <joint_name>left_engine_propeller_joint</joint_name>
    <thrust_coefficient>1</thrust_coefficient>
    <fluid_density>1000</fluid_density>
    <max_thrust_cmd>2.5</max_thrust_cmd>
    <min_thrust_cmd>-2.5</min_thrust_cmd>
    <propeller_diameter>0.1</propeller_diameter>
    <velocity_control>true</velocity_control>
  </plugin>

  <plugin filename="gz-sim-joint-position-controller-system" name="gz::sim::systems::JointPositionController">
    <joint_name>left_chasis_engine_joint</joint_name>
    <use_velocity_commands>true</use_velocity_commands>
    <topic>/wamv/left/thruster/joint/cmd_pos</topic>
  </plugin>

  <!-- Uncomment to enable the right thruster -->
  <plugin filename="gz-sim-thruster-system" name="gz::sim::systems::Thruster">
    <joint_name>right_engine_propeller_joint</joint_name>
    <thrust_coefficient>1</thrust_coefficient>
    <fluid_density>1000</fluid_density>
    <max_thrust_cmd>2.5</max_thrust_cmd>
    <min_thrust_cmd>-2.5</min_thrust_cmd>
    <propeller_diameter>0.1</propeller_diameter>
    <velocity_control>true</velocity_control>
  </plugin>

  <plugin filename="gz-sim-joint-position-controller-system" name="gz::sim::systems::JointPositionController">
    <joint_name>right_chasis_engine_joint</joint_name>
    <use_velocity_commands>true</use_velocity_commands>
    <topic>/wamv/right/thruster/joint/cmd_pos</topic>
  </plugin>
  <!-- Uncomment to produce buoyancy on the left hull -->
  <plugin filename="libSurface.so" name="maritime::Surface">
    <link_name>base_link</link_name>
    <hull_length>1.15</hull_length>
    <hull_radius>0.15</hull_radius>
    <fluid_level>1.0</fluid_level>
    <points>
      <point>  2.5  0.75  0.1</point>
      <point>  0.0  0.75  0.1</point>
      <point> -2.5  0.75  0.1</point>
      <point>  1.25  0.75  0.1</point>
      <point> -1.25  0.75  0.1</point>
      <point>  0.75  0.75  0.1</point>
      <point> -0.75  0.75  0.1</point>
    </points>
    <wavefield>
      <topic>/maritime/wavefield/parameters</topic>
    </wavefield>
  </plugin>
  
  <plugin filename="libSurface.so" name="maritime::Surface">
    <link_name>base_link</link_name>
    <hull_length>1.15</hull_length>
    <hull_radius>0.15</hull_radius>
    <fluid_level>1.0</fluid_level>
    <points>
      <point>  2.5 -0.75  0.1</point>
      <point>  0.0 -0.75  0.1</point>
      <point> -2.5 -0.75  0.1</point>
      <point>  1.25  -0.75  0.1</point>
      <point> -1.25  -0.75  0.1</point>
      <point>  0.75  -0.75  0.1</point>
      <point> -0.75  -0.75  0.1</point>
    </points>
    <wavefield>
      <topic>/maritime/wavefield/parameters</topic>
    </wavefield>
  </plugin>
  <!-- Uncomment to enable hydrodynamics -->
  <plugin filename="gz-sim-hydrodynamics-system" name="gz::sim::systems::Hydrodynamics">
    <link_name>base_link</link_name>
      <xDotU>0.0</xDotU>
      <yDotV>0.0</yDotV>
      <nDotR>0.0</nDotR>
      <xU>-4.0</xU>
      <xAbsU>6.0</xAbsU>
      <yV>-4.0</yV>
      <yAbsV>4.0</yAbsV>
      <zW>-80.0</zW>     <!-- Strong vertical damping -->
      <kP>-50.0</kP>     <!-- Strong roll damping -->
      <mQ>-100.0</mQ>    <!-- Strong pitch damping -->
      <nR>-70.0</nR>     <!-- Strong yaw damping -->
      <nAbsR>32.0</nAbsR>
  </plugin>
  <plugin
		 filename="gz-sim-joint-controller-system"
		 name="gz::sim::systems::JointController">
		 <joint_name>j1</joint_name>
		 <use_force_commands>True</use_force_commands>
    <p_gain> 50.0</p_gain>
  </plugin>

  <plugin
		 filename="gz-sim-joint-controller-system"
		 name="gz::sim::systems::JointController">
		 <joint_name>j2</joint_name>
		 <use_force_commands>True</use_force_commands>
     <p_gain> 50.0</p_gain>
	</plugin>
  
  <link name="gr">
    <pose>1.65 0 0.15 0 0 0</pose>
    <collision name="collision">
    <geometry>
      <mesh>
        <uri>meshes/gr.dae</uri>
        <scale>0.08 0.08 0.08</scale>
      </mesh>
    </geometry>
  </collision>
  <visual name="visual">
    <geometry>
      <mesh>
        <uri>meshes/gr.dae</uri>
        <scale>0.08 0.08 0.08</scale>
      </mesh>
    </geometry>
  </visual>
  </link>
  <link name="gun">
    <pose>1.65 0 0.48 0 0 0</pose>
    <collision name="collision">
    <geometry>
      <mesh>
        <uri>meshes/gun.dae</uri>
        <scale>0.08 0.08 0.08</scale>
      </mesh>
    </geometry>
  </collision>
  <visual name="visual">
    <geometry>
      <mesh>
        <uri>meshes/gun.dae</uri>
        <scale>0.08 0.08 0.08</scale>
      </mesh>
    </geometry>
  </visual>
  </link>

  <joint name="j2" type="revolute">
    <parent>base_link</parent>
    <child>gr</child>
    <axis>
      <xyz>0 0 1</xyz>
      <limit>
      <effort>10</effort>
      <velocity>0.3</velocity>
      </limit>
    </axis>
  </joint>
  <joint name="j1" type="revolute">
    <pose>0 0 0 0 0 0</pose>
    <parent>gr</parent>
    <child>gun</child>
    <axis>
      <xyz>0 1 0</xyz>
      <limit>
      <lower>-1.57</lower>
      <upper>1.57 </upper>
      <effort>10</effort>
      <velocity>0.3</velocity>
      </limit>
    </axis>
  </joint>

</model>

</sdf>